Workbook

Sheet Anbud
A1: LODET
A2: Anbudsförslag — utkast för granskning
A4: Projekt | B4: VÄG 875, GC SUNDBORN
A5: Dokumentnr | B5: 1E12MF10
A6: Status | B6: PROJEKT
A7: Datum | B7: 2025-06-12
A8: Genererat av Lodet | B8: 2026-04-30 (utkast v1)
A11: AMA-kod | B11: Beskrivning | C11: Enhet | D11: Antal | E11: À-pris (förslag) | F11: Belopp (förslag) | G11: Konf. | H11: Träffar | I11: À-pris (justerat) | J11: Belopp (justerat) | K11: Kommentar
A12: B — Förarbeten, hjälparbeten, saneringsarbeten
A13: BBC.6 | B13: Undersökning av befintliga ledningar | C13: — | F13: 1 | G13: låg | J13: =IF(I13<>"",I13*D13,F13) -> 1 | K13: Ingen historisk match — manuell prissättning krävs
A14: BEC.611 | B14: Armatur B1 | C14: st | D14: 29 | E14: 617 | F14: =D14*E14 -> 17893 | G14: medel | H14: 4 | J14: =IF(I14<>"",I14*D14,F14) -> 17893 | K14: 4 historiska träffar, indexjusterat E84
A15: BED.61 | B15: Stolpcentraler | C15: st | D15: 29 | E15: 387 | F15: =D15*E15 -> 11223 | G15: låg | H15: 2 | J15: =IF(I15<>"",I15*D15,F15) -> 11223 | K15: 2 historiska träffar, indexjusterat E84
A16: BED.61 | B16: Belysningsstolpar | C16: st | D16: 29 | E16: 439 | F16: =D16*E16 -> 12731 | G16: låg | H16: 2 | J16: =IF(I16<>"",I16*D16,F16) -> 12731 | K16: 2 historiska träffar, indexjusterat E84
A17: BED.61 | B17: Belysningskabel <30-90 0/700-0/830 | C17: m | D17: 310 | E17: 29 | F17: =D17*E17 -> 8990 | G17: låg | H17: 2 | J17: =IF(I17<>"",I17*D17,F17) -> 8990 | K17: 2 historiska träffar, indexjusterat E84
A18: BED.61 | B18: Belysningskabel <30-90 0/300 | C18: m | D18: 40 | E18: 29 | F18: =D18*E18 -> 1160 | G18: låg | H18: 2 | J18: =IF(I18<>"",I18*D18,F18) -> 1160 | K18: 2 historiska träffar, indexjusterat E84
A19: BED.61 | B19: Belysningskabel <30°–90° 0/300-0/560 | C19: m | D19: 290 | E19: 29 | F19: =D19*E19 -> 8410 | G19: medel | H19: 8 | J19: =IF(I19<>"",I19*D19,F19) -> 8410 | K19: 8 historiska träffar, indexjusterat E84
A20: BED.61 | B20: Belysningskabel <30°–90° sektion 0/560-0/700 | C20: m | D20: 20 | E20: 29 | F20: =D20*E20 -> 580 | G20: hög | H20: 6 | J20: =IF(I20<>"",I20*D20,F20) -> 580 | K20: 6 historiska träffar, indexjusterat E84
A21: BED.61 | B21: Belysningskabel <30°–90° sektion 0/000-0/300 | C21: m | D21: 340 | E21: 29 | F21: =D21*E21 -> 9860 | G21: medel | H21: 3 | J21: =IF(I21<>"",I21*D21,F21) -> 9860 | K21: 3 historiska träffar, indexjusterat E84
A22: BED.61 | B22: Belysningskabel <30° 0/830-0/961 | C22: m | D22: 40 | E22: 29 | F22: =D22*E22 -> 1160 | G22: medel | H22: 3 | J22: =IF(I22<>"",I22*D22,F22) -> 1160 | K22: 3 historiska träffar, indexjusterat E84
A23: BED.61 | B23: Belysningsfundament | C23: st | D23: 29 | E23: 539 | F23: =D23*E23 -> 15631 | G23: låg | H23: 2 | J23: =IF(I23<>"",I23*D23,F23) -> 15631 | K23: 2 historiska träffar, indexjusterat E84
A24: BJD.1 | B24: Stomnät | C24: — | F24: 1 | G24: låg | J24: =IF(I24<>"",I24*D24,F24) -> 1 | K24: Ingen historisk match — manuell prissättning krävs
A25: BJD.26 | B25: Inmätning av el- och teleinstallationer | C25: — | F25: 1 | G25: låg | J25: =IF(I25<>"",I25*D25,F25) -> 1 | K25: Ingen historisk match — manuell prissättning krävs
A26: BJD.36 | B26: Utsättning av el- och teleinstallationer | C26: — | F26: 1 | G26: låg | J26: =IF(I26<>"",I26*D26,F26) -> 1 | K26: Ingen historisk match — manuell prissättning krävs
A27: S — Apparater, ledningar m.m. i el- och telesystem
A28: SBB.211 | B28: Montering av fundament till kabelskåp(belysning) | C28: st | D28: 1 | E28: 6245 | F28: =D28*E28 -> 6245 | G28: medel | H28: 4 | J28: =IF(I28<>"",I28*D28,F28) -> 6245 | K28: 4 historiska träffar, indexjusterat E84
A29: SBB.211 | B29: Montering av fundament till kabelskåp(styrutrustning) | C29: st | D29: 1 | E29: 6369 | F29: =D29*E29 -> 6369 | G29: medel | H29: 8 | J29: =IF(I29<>"",I29*D29,F29) -> 6369 | K29: 8 historiska träffar, indexjusterat E84
A30: SBC.21 | B30: Belysningsstolpe typ DY01 | C30: st | D30: 21 | E30: 18379 | F30: =D30*E30 -> 385959 | G30: hög | H30: 5 | J30: =IF(I30<>"",I30*D30,F30) -> 385959 | K30: 5 historiska träffar, indexjusterat E84
A31: SBC.21 | B31: Belysningsstolpe typ DY02 | C31: st | D31: 4 | E31: 23942 | F31: =D31*E31 -> 95768 | G31: hög | H31: 8 | J31: =IF(I31<>"",I31*D31,F31) -> 95768 | K31: 8 historiska träffar, indexjusterat E84
A32: SBC.21 | B32: Belysningsstolpe typ DY03 | C32: st | D32: 5 | E32: 24969 | F32: =D32*E32 -> 124845 | G32: medel | H32: 6 | J32: =IF(I32<>"",I32*D32,F32) -> 124845 | K32: 6 historiska träffar, indexjusterat E84
A33: SBC.43 | B33: Stolpinsats, Ensto LCK4-06.1-06A, E7779866 eller likvärdig | C33: st | D33: 26 | E33: 1048 | F33: =D33*E33 -> 27248 | G33: hög | H33: 8 | J33: =IF(I33<>"",I33*D33,F33) -> 27248 | K33: 8 historiska träffar, indexjusterat E84
A34: SBC.43 | B34: Stolpinsats, Fingal Johnsson STS-2-4-MK 6A E77 718 16 eller likvärdig | C34: st | D34: 4 | E34: 1595 | F34: =D34*E34 -> 6380 | G34: låg | H34: 2 | J34: =IF(I34<>"",I34*D34,F34) -> 6380 | K34: 2 historiska träffar, indexjusterat E84
A35: SBN.112 | B35: SRN 50 för vägbelysning | C35: m | D35: 1150 | E35: 47 | F35: =D35*E35 -> 54050 | G35: medel | H35: 5 | J35: =IF(I35<>"",I35*D35,F35) -> 54050 | K35: 5 historiska träffar, indexjusterat E84
A36: SBN.122 | B36: SRS 110 för vägbelysning | C36: m | D36: 100 | E36: 151 | F36: =D36*E36 -> 15100 | G36: medel | H36: 4 | J36: =IF(I36<>"",I36*D36,F36) -> 15100 | K36: 4 historiska träffar, indexjusterat E84
A37: SCB.72 | B37: SE-N1XE-R 4G16, gul mantel | C37: m | D37: 1300 | E37: 233 | F37: =D37*E37 -> 302900 | G37: medel | H37: 8 | J37: =IF(I37<>"",I37*D37,F37) -> 302900 | K37: 8 historiska träffar, indexjusterat E84
A38: SCC.822 | B38: Förmonterad kabel för armaturer ingår i kod SND.1 | C38: — | G38: låg | J38: =IF(I38<>"",I38*D38,F38) -> 0 | K38: Ingen historisk match — manuell prissättning krävs
A39: SEC.22 | B39: Diazed gG 6A (stolpcentraler) | C39: st | D39: 34 | E39: 1 | F39: =D39*E39 -> 34 | G39: medel | H39: 8 | J39: =IF(I39<>"",I39*D39,F39) -> 34 | K39: 8 historiska träffar, indexjusterat E84
A40: SKB.32 | B40: Montering kabelskåp för lågspänning(belysningscentral) | C40: st | D40: 1 | E40: 10945 | F40: =D40*E40 -> 10945 | G40: medel | H40: 6 | J40: =IF(I40<>"",I40*D40,F40) -> 10945 | K40: 6 historiska träffar, indexjusterat E84
A41: SKB.32 | B41: Montering kabelskåp för lågspänning(styrutrustning) | C41: st | D41: 1 | E41: 5634 | F41: =D41*E41 -> 5634 | G41: hög | H41: 5 | J41: =IF(I41<>"",I41*D41,F41) -> 5634 | K41: 5 historiska träffar, indexjusterat E84
A42: SND.1 | B42: Fagerhult Opalume 306200-24761 | C42: st | D42: 25 | E42: 16493 | F42: =D42*E42 -> 412325 | G42: medel | H42: 8 | J42: =IF(I42<>"",I42*D42,F42) -> 412325 | K42: 8 historiska träffar, indexjusterat E84
A43: SND.1 | B43: Fagerhult Opalume 306200-24766 | C43: st | D43: 4 | E43: 14696 | F43: =D43*E43 -> 58784 | G43: låg | H43: 2 | J43: =IF(I43<>"",I43*D43,F43) -> 58784 | K43: 2 historiska träffar, indexjusterat E84
...

Sheet Sammanfattning
A1: SAMMANFATTNING
A3: Matchningskvalitet
A4: Totalt antal rader | B4: 48
A5: Rader med AI-förslag | B5: 26
A6: Rader utan match (manuell) | B6: 22
A7: Klumpsummerader | B7: 22
A10: Konfidensfördelning
A11: Hög konfidens | B11: =COUNTIF(Anbud!G:G, "hög") -> 5
A12: Medel konfidens | B12: =COUNTIF(Anbud!G:G, "medel") -> 14
A13: Låg konfidens | B13: =COUNTIF(Anbud!G:G, "låg") -> 29
A16: Anbudssumma
A17: Förslag (AI) | B17: =SUM(Anbud!F:F) -> 3483420
A18: Justerat (efter granskning) | B18: =SUM(Anbud!J:J) -> 3483420
A21: Att granska innan inlämning
A22: ☐ Kontrollera alla rader med låg konfidens — manuell prissättning kan krävas
A23: ☐ Verifiera UE-poster (kolumn med UE-kategori, ej i denna demo)
A24: ☐ Granska klumpsummerader och sätt rätt belopp där de är 1 kr (placeholder)
A25: ☐ Lägg på generellt påslag för marknadsläge (om relevant)
A26: ☐ Kontrollera att alla AMA-koder från förfrågan finns med

Sheet Historik per rad
A1: HISTORISKA MATCHNINGAR
A2: Per anbudsrad: vilka tidigare offerter användes som referens?
A4: AMA-kod | B4: Beskrivning | C4: Match-rang | D4: Källprojekt | E4: Källdatum | F4: Hist. à-pris | G4: Indexjusterat | H4: Likhet
A5: BEC.611 | B5: Armatur B1 | C5: 1 | D5: Vägbelysning Rv 84, Ljusdal | E5: 2025-01-20 | F5: 573 | G5: 596 | H5: 0.79
C6: 2 | D6: Kv. Tegelbruket etapp 2, Sundsvall | E6: 2024-03-15 | F6: 663 | G6: 690 | H6: 0.88
C7: 3 | D7: GC-väg Skogsbacken, Sollefteå | E7: 2023-09-22 | F7: 629 | G7: 654 | H7: 0.82
A9: BED.61 | B9: Stolpcentraler | C9: 1 | D9: Kv. Tegelbruket etapp 2, Sundsvall | E9: 2024-03-15 | F9: 376 | G9: 391 | H9: 0.94
C10: 2 | D10: GC-väg Skogsbacken, Sollefteå | E10: 2023-09-22 | F10: 392 | G10: 408 | H10: 0.81
C11: 3 | D11: Belysning Industrigatan, Härnösand | E11: 2024-11-08 | F11: 335 | G11: 348 | H11: 0.91
A13: BED.61 | B13: Belysningsstolpar | C13: 1 | D13: Renovering Storgatan, Bollnäs | E13: 2023-06-14 | F13: 424 | G13: 441 | H13: 0.91
C14: 2 | D14: Vägbelysning Rv 84, Ljusdal | E14: 2025-01-20 | F14: 410 | G14: 426 | H14: 0.89
C15: 3 | D15: Kv. Tegelbruket etapp 2, Sundsvall | E15: 2024-03-15 | F15: 402 | G15: 418 | H15: 0.96
A17: BED.61 | B17: Belysningskabel <30-90 0/700-0/830 | C17: 1 | D17: Vägbelysning Rv 84, Ljusdal | E17: 2025-01-20 | F17: 25 | G17: 26 | H17: 0.87
C18: 2 | D18: Kv. Tegelbruket etapp 2, Sundsvall | E18: 2024-03-15 | F18: 30 | G18: 31 | H18: 0.93
C19: 3 | D19: GC-väg Skogsbacken, Sollefteå | E19: 2023-09-22 | F19: 25 | G19: 26 | H19: 0.81
A21: BED.61 | B21: Belysningskabel <30-90 0/300 | C21: 1 | D21: Vägbelysning Rv 84, Ljusdal | E21: 2025-01-20 | F21: 30 | G21: 31 | H21: 0.89
C22: 2 | D22: Kv. Tegelbruket etapp 2, Sundsvall | E22: 2024-03-15 | F22: 27 | G22: 28 | H22: 0.89
C23: 3 | D23: GC-väg Skogsbacken, Sollefteå | E23: 2023-09-22 | F23: 28 | G23: 29 | H23: 0.83
A25: BED.61 | B25: Belysningskabel <30°–90° 0/300-0/560 | C25: 1 | D25: Vägbelysning Rv 84, Ljusdal | E25: 2025-01-20 | F25: 28 | G25: 29 | H25: 0.95
C26: 2 | D26: Kv. Tegelbruket etapp 2, Sundsvall | E26: 2024-03-15 | F26: 30 | G26: 31 | H26: 0.8
C27: 3 | D27: GC-väg Skogsbacken, Sollefteå | E27: 2023-09-22 | F27: 31 | G27: 32 | H27: 0.92
A29: BED.61 | B29: Belysningskabel <30°–90° sektion 0/560-0/700 | C29: 1 | D29: Renovering Storgatan, Bollnäs | E29: 2023-06-14 | F29: 30 | G29: 31 | H29: 0.84
C30: 2 | D30: Vägbelysning Rv 84, Ljusdal | E30: 2025-01-20 | F30: 26 | G30: 27 | H30: 0.81
C31: 3 | D31: Kv. Tegelbruket etapp 2, Sundsvall | E31: 2024-03-15 | F31: 24 | G31: 25 | H31: 0.91
A33: BED.61 | B33: Belysningskabel <30°–90° sektion 0/000-0/300 | C33: 1 | D33: Kv. Tegelbruket etapp 2, Sundsvall | E33: 2024-03-15 | F33: 30 | G33: 31 | H33: 0.95
C34: 2 | D34: GC-väg Skogsbacken, Sollefteå | E34: 2023-09-22 | F34: 30 | G34: 31 | H34: 0.87
C35: 3 | D35: Belysning Industrigatan, Härnösand | E35: 2024-11-08 | F35: 25 | G35: 26 | H35: 0.89
